2023-09-28-15:36:26   [info]: Initialized trainer for run: final_models/model_final_2
2023-09-28-15:36:26   [info]: Using device: cuda
2023-09-28-15:36:26   [info]: Calling: initialize_model...
2023-09-28-15:36:26   [warn]: Cannot watch model without WandB
2023-09-28-15:36:26   [info]: Initialized model
2023-09-28-15:36:26   [info]: Calling: load_checkpoint...
2023-09-28-15:36:26   [error]: Checkpoint could not been load from: /home/user/denninge/human-pose-forecasting/experiments/final_models/model_final_2/checkpoints/checkpoint_epoch_80.pth
2023-09-28-15:36:26   [error]: Exception: [Errno 2] No such file or directory: '/home/user/denninge/human-pose-forecasting/experiments/final_models/model_final_2/checkpoints/checkpoint_epoch_80.pth'
2023-09-28-15:36:26   [info]: Calling: initialize_evaluation...
2023-09-28-15:36:26   [info]: Load the evaluation data for each action
2023-09-28-15:36:26   [error]: Traceback (most recent call last):
  File "/home/user/denninge/human-pose-forecasting/src/utils/logging.py", line 39, in try_call_log
    return func(*args, **kwargs)
           ^^^^^^^^^^^^^^^^^^^^^
  File "/home/user/denninge/human-pose-forecasting/src/Session.py", line 135, in initialize_evaluation
    self.evaluation_engine.initialize_distance_evaluation(
  File "/home/user/denninge/human-pose-forecasting/src/evaluation/EvaluationEngine.py", line 188, in initialize_distance_evaluation
    target_frames =  np.ceil(np.array(prediction_timesteps) / self.step_size).astype(int)
                                                              ^^^^^^^^^^^^^^
AttributeError: 'EvaluationEngine' object has no attribute 'step_size'

